{
    "model_class": "Job",
    "id": "266ebae484bfe9d7",
    "history_id": "fbc0a16fda789409",
    "tool_id": "toolshed.g2.bx.psu.edu/repos/devteam/fastq_groomer/fastq_groomer/1.1.5+galaxy2",
    "state": "error",
    "exit_code": 1,
    "create_time": "2024-11-19T06:34:16.004467",
    "update_time": "2024-11-19T06:34:27.952905",
    "galaxy_version": "24.1",
    "external_id": "gxy-4pnw7",
    "handler": null,
    "job_runner_name": null,
    "command_line": "gx-fastq-groomer '/galaxy/server/database/objects/9/9/c/dataset_99cabee7-04c2-4fc4-9a11-d8b62855e0b5.dat' sanger '/galaxy/server/database/objects/5/0/4/dataset_504f82bc-5885-4216-ab2b-dcdbbfd542c0.dat' sanger ascii summarize_input --no-fix-id",
    "user_email": "tests@fake.org",
    "command_version": "",
    "params": {
        "__input_ext": "\"input\"",
        "dbkey": "\"?\"",
        "chromInfo": "\"/cvmfs/data.galaxyproject.org/managed/len/ucsc/?.len\"",
        "options_type": "{\"__current_case__\": 1, \"fix_id\": false, \"force_quality_encoding\": \"ascii\", \"options_type_selector\": \"advanced\", \"output_type\": \"sanger\", \"summarize_input\": \"summarize_input\"}",
        "input_type": "\"sanger\""
    },
    "inputs": {
        "input_file": {
            "id": "d959a7e912162426",
            "src": "hda",
            "uuid": "99cabee7-04c2-4fc4-9a11-d8b62855e0b5"
        }
    },
    "outputs": {
        "output_file": {
            "id": "266ebae484bfe9d7",
            "src": "hda",
            "uuid": "504f82bc-5885-4216-ab2b-dcdbbfd542c0"
        }
    },
    "copied_from_job_id": null,
    "output_collections": {},
    "tool_stdout": "There was an error reading your input file. Your input file is likely malformed.\nIt is suggested that you double-check your original input file for errors -- helpful information for this purpose has been provided below.\nHowever, if you think that you have encountered an actual error with this tool, please do tell us by using the bug reporting mechanism.\n\nThe reported error is: 'Invalid FASTQ file: quality score identifier (+invalid line)                         does not match sequence identifier (@FAKE-1).'.\nThe error occurred at the start of your file and no valid FASTQ reads were found.\nThe error in your file occurs between lines '1' and '3', which corresponds to byte-offsets '0' and '33', and contains the text (33 of 33 bytes shown):\n\n@FAKE-1\nACGTACGTAC\n+invalid line\n\n",
    "tool_stderr": "Traceback (most recent call last):\n  File \"/usr/local/bin/gx-fastq-groomer\", line 10, in <module>\n    sys.exit(main())\n             ^^^^^^\n  File \"/usr/local/lib/python3.11/site-packages/galaxy_utils/sequence/scripts/fastq_groomer.py\", line 99, in main\n    Groomer().run()\n  File \"/usr/local/lib/python3.11/site-packages/galaxy_utils/sequence/scripts/fastq_groomer.py\", line 48, in run\n    for read_count, fastq_read in enumerate(reader):\n  File \"/usr/local/lib/python3.11/site-packages/galaxy_utils/sequence/fastq.py\", line 683, in __iter__\n    yield next(self)\n          ^^^^^^^^^^\n  File \"/usr/local/lib/python3.11/site-packages/galaxy_utils/sequence/fastq.py\", line 742, in __next__\n    raise e\n  File \"/usr/local/lib/python3.11/site-packages/galaxy_utils/sequence/fastq.py\", line 724, in __next__\n    block = super(fastqVerboseErrorReader, self).__next__()\n            ^^^^^^^^^^^^^^^^^^^^^^^^^^^^^^^^^^^^^^^^^^^^^^^\n  File \"/usr/local/lib/python3.11/site-packages/galaxy_utils/sequence/fastq.py\", line 621, in __next__\n    self._read_fastq_sequence(rval, id_line)\n  File \"/usr/local/lib/python3.11/site-packages/galaxy_utils/sequence/fastq.py\", line 666, in _read_fastq_sequence\n    raise fastqFormatError(\ngalaxy_utils.sequence.fastq.fastqFormatError: Invalid FASTQ file: quality score identifier (+invalid line)                         does not match sequence identifier (@FAKE-1).\n",
    "job_stdout": "",
    "job_stderr": "",
    "stdout": "There was an error reading your input file. Your input file is likely malformed.\nIt is suggested that you double-check your original input file for errors -- helpful information for this purpose has been provided below.\nHowever, if you think that you have encountered an actual error with this tool, please do tell us by using the bug reporting mechanism.\n\nThe reported error is: 'Invalid FASTQ file: quality score identifier (+invalid line)                         does not match sequence identifier (@FAKE-1).'.\nThe error occurred at the start of your file and no valid FASTQ reads were found.\nThe error in your file occurs between lines '1' and '3', which corresponds to byte-offsets '0' and '33', and contains the text (33 of 33 bytes shown):\n\n@FAKE-1\nACGTACGTAC\n+invalid line\n\n",
    "stderr": "Traceback (most recent call last):\n  File \"/usr/local/bin/gx-fastq-groomer\", line 10, in <module>\n    sys.exit(main())\n             ^^^^^^\n  File \"/usr/local/lib/python3.11/site-packages/galaxy_utils/sequence/scripts/fastq_groomer.py\", line 99, in main\n    Groomer().run()\n  File \"/usr/local/lib/python3.11/site-packages/galaxy_utils/sequence/scripts/fastq_groomer.py\", line 48, in run\n    for read_count, fastq_read in enumerate(reader):\n  File \"/usr/local/lib/python3.11/site-packages/galaxy_utils/sequence/fastq.py\", line 683, in __iter__\n    yield next(self)\n          ^^^^^^^^^^\n  File \"/usr/local/lib/python3.11/site-packages/galaxy_utils/sequence/fastq.py\", line 742, in __next__\n    raise e\n  File \"/usr/local/lib/python3.11/site-packages/galaxy_utils/sequence/fastq.py\", line 724, in __next__\n    block = super(fastqVerboseErrorReader, self).__next__()\n            ^^^^^^^^^^^^^^^^^^^^^^^^^^^^^^^^^^^^^^^^^^^^^^^\n  File \"/usr/local/lib/python3.11/site-packages/galaxy_utils/sequence/fastq.py\", line 621, in __next__\n    self._read_fastq_sequence(rval, id_line)\n  File \"/usr/local/lib/python3.11/site-packages/galaxy_utils/sequence/fastq.py\", line 666, in _read_fastq_sequence\n    raise fastqFormatError(\ngalaxy_utils.sequence.fastq.fastqFormatError: Invalid FASTQ file: quality score identifier (+invalid line)                         does not match sequence identifier (@FAKE-1).\n",
    "job_messages": [
        {
            "code_desc": "",
            "desc": "Fatal error: Exit code 1 ()",
            "error_level": 3,
            "exit_code": 1,
            "type": "exit_code"
        }
    ],
    "dependencies": [],
    "job_metrics": [
        {
            "title": "Job Runtime (Wall Clock)",
            "value": "0 seconds",
            "plugin": "core",
            "name": "runtime_seconds",
            "raw_value": "0E-7"
        },
        {
            "title": "Job End Time",
            "value": "2024-11-19 06:34:17",
            "plugin": "core",
            "name": "end_epoch",
            "raw_value": "1731998057.0000000"
        },
        {
            "title": "Job Start Time",
            "value": "2024-11-19 06:34:17",
            "plugin": "core",
            "name": "start_epoch",
            "raw_value": "1731998057.0000000"
        },
        {
            "title": "Memory Allocated (MB)",
            "value": "8160",
            "plugin": "core",
            "name": "galaxy_memory_mb",
            "raw_value": "8160.0000000"
        },
        {
            "title": "Cores Allocated",
            "value": "1",
            "plugin": "core",
            "name": "galaxy_slots",
            "raw_value": "1.0000000"
        }
    ]
}
